Workbook

Sheet Data
A1: 5 | B1: apple | C1: 45306 | E1: x | F1: y | G1: z | H1: 1 | I1: 9 | J1: -100
A2: 3 | B2: banana | C2: 45338 | E2: 10 | F2: 20 | G2: 30 | H2: 3 | I2: 7 | J2: 30
A3: 8 | B3: cherry | C3: 45368 | H3: 5 | I3: 5 | J3: 40
A4: 1 | B4: apple | C4: 45400 | H4: 7 | I4: 3 | J4: 50
A5: 9 | B5: date | C5: 45431 | H5: 9 | I5: 1 | J5: 60
A6: 2 | B6: banana | C6: 45463
A7: 7 | B7: apple | C7: 45494
A8: 4 | B8: fig | C8: 45526

Sheet Calc
A1: =SUM(Data!A1:A8) -> 39 | B1: SUM(Data!A1:A8)
A2: =AVERAGE(Data!A1:A8) -> 4.875 | B2: AVERAGE(Data!A1:A8)
A3: =MIN(Data!A1:A8) -> 1 | B3: MIN(Data!A1:A8)
A4: =MAX(Data!A1:A8) -> 9 | B4: MAX(Data!A1:A8)
A5: =COUNT(Data!A1:A8) -> 8 | B5: COUNT(Data!A1:A8)
A6: =COUNTA(Data!B1:B9) -> 8 | B6: COUNTA(Data!B1:B9)
A7: =MEDIAN(Data!A1:A8) -> 4.5 | B7: MEDIAN(Data!A1:A8)
A8: =LARGE(Data!A1:A8,2) -> 8 | B8: LARGE(Data!A1:A8,2)
A9: =SMALL(Data!A1:A8,3) -> 3 | B9: SMALL(Data!A1:A8,3)
A10: =PRODUCT(Data!A1:A3) -> 120 | B10: PRODUCT(Data!A1:A3)
A11: =SUMIF(Data!B1:B8,"apple",Data!A1:A8) -> 13 | B11: SUMIF(Data!B1:B8,"apple",Data!A1:A8)
A12: =COUNTIF(Data!B1:B8,"a*") -> 3 | B12: COUNTIF(Data!B1:B8,"a*")
A13: =COUNTIF(Data!A1:A8,">4") -> 4 | B13: COUNTIF(Data!A1:A8,">4")
A14: =COUNTIF(Data!A1:A8,"<>5") -> 7 | B14: COUNTIF(Data!A1:A8,"<>5")
A15: =SUMIFS(Data!A1:A8,Data!B1:B8,"apple",Data!A1:A8,">=5") -> 12 | B15: SUMIFS(Data!A1:A8,Data!B1:B8,"apple",Data!A1:A8,">=5")
A16: =AVERAGEIF(Data!B1:B8,"banana",Data!A1:A8) -> 2.5 | B16: AVERAGEIF(Data!B1:B8,"banana",Data!A1:A8)
A17: =COUNTIFS(Data!B1:B8,"apple",Data!A1:A8,"<6") -> 2 | B17: COUNTIFS(Data!B1:B8,"apple",Data!A1:A8,"<6")
A18: =_xlfn.MAXIFS(Data!A1:A8,Data!B1:B8,"apple") -> 7 | B18: _xlfn.MAXIFS(Data!A1:A8,Data!B1:B8,"apple")
A19: =_xlfn.MINIFS(Data!A1:A8,Data!B1:B8,"apple") -> 1 | B19: _xlfn.MINIFS(Data!A1:A8,Data!B1:B8,"apple")
A20: =SUMPRODUCT(Data!A1:A8,Data!A1:A8) -> 249 | B20: SUMPRODUCT(Data!A1:A8,Data!A1:A8)
A21: =SUMPRODUCT((Data!B1:B8="apple")*(Data!A1:A8)) -> 13 | B21: SUMPRODUCT((Data!B1:B8="apple")*(Data!A1:A8))
A22: =COUNTBLANK(Data!B1:B9) -> 1 | B22: COUNTBLANK(Data!B1:B9)
A23: =SUM(Data!A:A) -> 39 | B23: SUM(Data!A:A)
A24: =SUMSQ(Data!A1:A3) -> 98 | B24: SUMSQ(Data!A1:A3)
A25: =STDEV(Data!A1:A8) -> 2.9001232 | B25: STDEV(Data!A1:A8)
A26: =VAR(Data!A1:A8) -> 8.4107143 | B26: VAR(Data!A1:A8)
A27: =ROUND(Data!A1/3,2) -> 1.67 | B27: ROUND(Data!A1/3,2)
A28: =ROUND(2.5,0) -> 3 | B28: ROUND(2.5,0)
A29: =ROUND(-2.5,0) -> -3 | B29: ROUND(-2.5,0)
A30: =ROUND(1.005,2) -> 1.01 | B30: ROUND(1.005,2)
A31: =ROUND(1234.567,-2) -> 1200 | B31: ROUND(1234.567,-2)
A32: =ROUNDUP(2.341,2) -> 2.35 | B32: ROUNDUP(2.341,2)
A33: =ROUNDDOWN(-2.349,2) -> -2.34 | B33: ROUNDDOWN(-2.349,2)
A34: =TRUNC(8.97) -> 8 | B34: TRUNC(8.97)
A35: =TRUNC(8.97,1) -> 8.9 | B35: TRUNC(8.97,1)
A36: =INT(-3.2) -> -4 | B36: INT(-3.2)
A37: =MOD(-7,3) -> 2 | B37: MOD(-7,3)
A38: =MOD(7,-3) -> -2 | B38: MOD(7,-3)
A39: =POWER(2,10) -> 1024 | B39: POWER(2,10)
A40: =SQRT(16) -> 4 | B40: SQRT(16)
...
